Workbook

Sheet README
A1: LA28 QUALIFICATION DATABASE — v4
A3: FENCING, CRICKET, FOOTBALL AND BASKETBALL ARE COMPLETE (green rows).
A5: WHAT CRICKET ADDED TO THE SCHEMA
A6: 1. gate_ranking_id — new column on Links. Cricket’s host place is NOT automatic: the USA gets it
A7: only if it appears at rank 15 or better between 30 Jun and 31 Dec 2026. The berth comes from
A8: HOST_USA but a ranking decides whether it lands. Fencing had no conditional berths; several
A9: other sports will. Blank for every fencing row.
A10: 2. status = CONDITIONAL — a competition that may not happen. The West Indies Nations Regional
A11: Tournament exists only if West Indies finishes inside the eight highest-ranked teams not yet
A12: qualified. A competition whose existence depends on a ranking outcome.
A14: THE WEST INDIES ASYMMETRY — read this before trusting any cut-line
A15: West Indies holds a position in the ICC rankings but is not an IOC NOC and cannot take a quota
... A109: Modelled on link fbl-005 as one row (recipient conditional, count and source fixed).

Sheet Olympic_Events
A1: olympic_event_id | B1: sport | C1: gender | D1: event_name | E1: quota_total | F1: quota_unit | G1: ioc_doc_url | H1: notes | I1: berth_check
A2: la28-fencing-ind-foil-m | B2: Fencing | C2: M | D2: Men’s Individual Foil | E2: 10 | F2: ATHLETE | G2: https://stillmed.olympics.com/media/Documents/Olympic-Games/LA28/FEN-LA28-Qualification-System.pdf | H2: 10 individual quota places. The 24 athletes who qualify via team qualification also compete here but hold TEAM places, not these 10 (D.2). Field size 34–37. Max 3 athletes per NOC per weapon overall. | I2: =IF(E2="","no quota",IF(SUMIF(Links!D:D,A2,Links!G:G)=E2,"OK","MISMATCH: "&SUMIF(Links!D:D,A2,Links!G:G)&" of "&E2)) -> OK
A3: la28-fencing-team-foil-m | B3: Fencing | C3: M | D3: Men’s Team Foil | E3: 8 | F3: TEAM | G3: https://stillmed.olympics.com/media/Documents/Olympic-Games/LA28/FEN-LA28-Qualification-System.pdf | H3: 8 teams of 3 = 24 athletes. Max 9 teams if host adds one. 6 team events x 24 = 144 athlete places (B.4). | I3: =IF(E3="","no quota",IF(SUMIF(Links!D:D,A3,Links!G:G)=E3,"OK","MISMATCH: "&SUMIF(Links!D:D,A3,Links!G:G)&" of "&E3)) -> OK
A4: la28-fencing-ind-epee-m | B4: Fencing | C4: M | D4: Men’s Individual Épée | E4: 10 | F4: ATHLETE | G4: https://stillmed.olympics.com/media/Documents/Olympic-Games/LA28/FEN-LA28-Qualification-System.pdf | H4: 10 individual quota places. The 24 athletes who qualify via team qualification also compete here but hold TEAM places, not these 10 (D.2). Field size 34–37. Max 3 athletes per NOC per weapon overall. | I4: =IF(E4="","no quota",IF(SUMIF(Links!D:D,A4,Links!G:G)=E4,"OK","MISMATCH: "&SUMIF(Links!D:D,A4,Links!G:G)&" of "&E4)) -> OK
A5: la28-fencing-team-epee-m | B5: Fencing | C5: M | D5: Men’s Team Épée | E5: 8 | F5: TEAM | G5: https://stillmed.olympics.com/media/Documents/Olympic-Games/LA28/FEN-LA28-Qualification-System.pdf | H5: 8 teams of 3 = 24 athletes. Max 9 teams if host adds one. 6 team events x 24 = 144 athlete places (B.4). | I5: =IF(E5="","no quota",IF(SUMIF(Links!D:D,A5,Links!G:G)=E5,"OK","MISMATCH: "&SUMIF(Links!D:D,A5,Links!G:G)&" of "&E5)) -> OK
A6: la28-fencing-ind-sabre-m | B6: Fencing | C6: M | D6: Men’s Individual Sabre | E6: 10 | F6: ATHLETE | G6: https://stillmed.olympics.com/media/Documents/Olympic-Games/LA28/FEN-LA28-Qualification-System.pdf | H6: 10 individual quota places. The 24 athletes who qualify via team qualification also compete here but hold TEAM places, not these 10 (D.2). Field size 34–37. Max 3 athletes per NOC per weapon overall. | I6: =IF(E6="","no quota",IF(SUMIF(Links!D:D,A6,Links!G:G)=E6,"OK","MISMATCH: "&SUMIF(Links!D:D,A6,Links!G:G)&" of "&E6)) -> OK
A7: la28-fencing-team-sabre-m | B7: Fencing | C7: M | D7: Men’s Team Sabre | E7: 8 | F7: TEAM | G7: https://stillmed.olympics.com/media/Documents/Olympic-Games/LA28/FEN-LA28-Qualification-System.pdf | H7: 8 teams of 3 = 24 athletes. Max 9 teams if host adds one. 6 team events x 24 = 144 athlete places (B.4). | I7: =IF(E7="","no quota",IF(SUMIF(Links!D:D,A7,Links!G:G)=E7,"OK","MISMATCH: "&SUMIF(Links!D:D,A7,Links!G:G)&" of "&E7)) -> OK
A8: la28-fencing-ind-foil-w | B8: Fencing | C8: W | D8: Women’s Individual Foil | E8: 10 | F8: ATHLETE | G8: https://stillmed.olympics.com/media/Documents/Olympic-Games/LA28/FEN-LA28-Qualification-System.pdf | H8: 10 individual quota places. The 24 athletes who qualify via team qualification also compete here but hold TEAM places, not these 10 (D.2). Field size 34–37. Max 3 athletes per NOC per weapon overall. | I8: =IF(E8="","no quota",IF(SUMIF(Links!D:D,A8,Links!G:G)=E8,"OK","MISMATCH: "&SUMIF(Links!D:D,A8,Links!G:G)&" of "&E8)) -> OK
A9: la28-fencing-team-foil-w | B9: Fencing | C9: W | D9: Women’s Team Foil | E9: 8 | F9: TEAM | G9: https://stillmed.olympics.com/media/Documents/Olympic-Games/LA28/FEN-LA28-Qualification-System.pdf | H9: 8 teams of 3 = 24 athletes. Max 9 teams if host adds one. 6 team events x 24 = 144 athlete places (B.4). | I9: =IF(E9="","no quota",IF(SUMIF(Links!D:D,A9,Links!G:G)=E9,"OK","MISMATCH: "&SUMIF(Links!D:D,A9,Links!G:G)&" of "&E9)) -> OK
A10: la28-fencing-ind-epee-w | B10: Fencing | C10: W | D10: Women’s Individual Épée | E10: 10 | F10: ATHLETE | G10: https://stillmed.olympics.com/media/Documents/Olympic-Games/LA28/FEN-LA28-Qualification-System.pdf | H10: 10 individual quota places. The 24 athletes who qualify via team qualification also compete here but hold TEAM places, not these 10 (D.2). Field size 34–37. Max 3 athletes per NOC per weapon overall. | I10: =IF(E10="","no quota",IF(SUMIF(Links!D:D,A10,Links!G:G)=E10,"OK","MISMATCH: "&SUMIF(Links!D:D,A10,Links!G:G)&" of "&E10)) -> OK
A11: la28-fencing-team-epee-w | B11: Fencing | C11: W | D11: Women’s Team Épée | E11: 8 | F11: TEAM | G11: https://stillmed.olympics.com/media/Documents/Olympic-Games/LA28/FEN-LA28-Qualification-System.pdf | H11: 8 teams of 3 = 24 athletes. Max 9 teams if host adds one. 6 team events x 24 = 144 athlete places (B.4). | I11: =IF(E11="","no quota",IF(SUMIF(Links!D:D,A11,Links!G:G)=E11,"OK","MISMATCH: "&SUMIF(Links!D:D,A11,Links!G:G)&" of "&E11)) -> OK
A12: la28-fencing-ind-sabre-w | B12: Fencing | C12: W | D12: Women’s Individual Sabre | E12: 10 | F12: ATHLETE | G12: https://stillmed.olympics.com/media/Documents/Olympic-Games/LA28/FEN-LA28-Qualification-System.pdf | H12: 10 individual quota places. The 24 athletes who qualify via team qualification also compete here but hold TEAM places, not these 10 (D.2). Field size 34–37. Max 3 athletes per NOC per weapon overall. | I12: =IF(E12="","no quota",IF(SUMIF(Links!D:D,A12,Links!G:G)=E12,"OK","MISMATCH: "&SUMIF(Links!D:D,A12,Links!G:G)&" of "&E12)) -> OK
A13: la28-fencing-team-sabre-w | B13: Fencing | C13: W | D13: Women’s Team Sabre | E13: 8 | F13: TEAM | G13: https://stillmed.olympics.com/media/Documents/Olympic-Games/LA28/FEN-LA28-Qualification-System.pdf | H13: 8 teams of 3 = 24 athletes. Max 9 teams if host adds one. 6 team events x 24 = 144 athlete places (B.4). | I13: =IF(E13="","no quota",IF(SUMIF(Links!D:D,A13,Links!G:G)=E13,"OK","MISMATCH: "&SUMIF(Links!D:D,A13,Links!G:G)&" of "&E13)) -> OK
... A20: la28-basketball-w | B20: Basketball | C20: W | D20: Women’s Basketball (5x5) | E20: 12 | F20: TEAM | G20: https://stillmed.olympics.com/media/Documents/Olympic-Games/LA28/BKB-LA28-Qualification-System.pdf | H20: 12 teams of 12 = 144 athletes. Host place also subject to a FIBA Central Board decision in 2027. If the FWBWC 2026 winner is also the host, only one team qualifies directly and 11 come through the FWOQT. | I20: =IF(E20="","no quota",IF(SUMIF(Links!D:D,A20,Links!G:G)=E20,"OK","MISMATCH: "&SUMIF(Links!D:D,A20,Links!G:G)&" of "&E20)) -> OK

Sheet Competitions
A1: competition_id | B1: name | C1: sport | D1: gender | E1: confederation | F1: start_date | G1: end_date | H1: date_confidence | I1: location | J1: status | K1: format | L1: teams_count | M1: official_url | N1: source_ref | O1: confidence | P1: notes
A2: fie-senior-team-world-cup | B2: Senior Team World Cup competitions | C2: Fencing | D2: X | E2: GLOBAL | F2: 2027-04-01 | G2: 2028-04-01 | H2: APPROXIMATE | J2: SCHEDULED | K2: Category of events across the season · awards ranking points only | M2: https://fie.org/ | N2: D.1 | O2: FROM_IOC_DOC | P2: Category, not a single event. Awards points to the FIE Senior Team Ranking.
A3: fie-senior-team-world-championships | B3: Senior Team World Championships | C3: Fencing | D3: X | E3: GLOBAL | F3: 2027-04-01 | G3: 2028-04-01 | H3: APPROXIMATE | J3: SCHEDULED | K3: Category of events across the season · awards ranking points only | M3: https://fie.org/ | N3: D.1 | O3: FROM_IOC_DOC | P3: Category, not a single event. Awards points to the FIE Senior Team Ranking.
A4: fie-senior-team-continental-championships | B4: Senior Team Continental Championships | C4: Fencing | D4: X | E4: GLOBAL | F4: 2027-04-01 | G4: 2028-04-01 | H4: APPROXIMATE | J4: SCHEDULED | K4: Category of events across the season · awards ranking points only | M4: https://fie.org/ | N4: D.1 | O4: FROM_IOC_DOC | P4: Category, not a single event. Awards points to the FIE Senior Team Ranking.
A5: fie-individual-grand-prix | B5: Individual Grand Prix competitions | C5: Fencing | D5: X | E5: GLOBAL | F5: 2027-04-01 | G5: 2028-04-01 | H5: APPROXIMATE | J5: SCHEDULED | K5: Category of events across the season · awards ranking points only | M5: https://fie.org/ | N5: D.2 | O5: FROM_IOC_DOC | P5: Category, not a single event. Awards points to the FIE Individual Official Ranking.
A6: fie-individual-senior-world-cup | B6: Individual Senior World Cup competitions | C6: Fencing | D6: X | E6: GLOBAL | F6: 2027-04-01 | G6: 2028-04-01 | H6: APPROXIMATE | J6: SCHEDULED | K6: Category of events across the season · awards ranking points only | M6: https://fie.org/ | N6: D.2 | O6: FROM_IOC_DOC | P6: Category, not a single event. Awards points to the FIE Individual Official Ranking.
A7: fie-satellite-competitions | B7: Satellite competitions | C7: Fencing | D7: X | E7: GLOBAL | F7: 2027-04-01 | G7: 2028-04-01 | H7: APPROXIMATE | J7: SCHEDULED | K7: Category of events across the season · awards ranking points only | M7: https://fie.org/ | N7: D.2 | O7: FROM_IOC_DOC | P7: Category, not a single event. Awards points to the FIE Individual Official Ranking.
A8: fie-individual-senior-world-championships | B8: Individual Senior World Championships | C8: Fencing | D8: X | E8: GLOBAL | F8: 2027-04-01 | G8: 2028-04-01 | H8: APPROXIMATE | J8: SCHEDULED | K8: Category of events across the season · awards ranking points only | M8: https://fie.org/ | N8: D.2 | O8: FROM_IOC_DOC | P8: Category, not a single event. Awards points to the FIE Individual Official Ranking.
A9: fie-individual-senior-continental-championships | B9: Individual Senior Continental Championships | C9: Fencing | D9: X | E9: GLOBAL | F9: 2027-04-01 | G9: 2028-04-01 | H9: APPROXIMATE | J9: SCHEDULED | K9: Category of events across the season · awards ranking points only | M9: https://fie.org/ | N9: D.2 | O9: FROM_IOC_DOC | P9: Category, not a single event. Awards points to the FIE Individual Official Ranking.
A10: fie-zonal-qualifying-europe | B10: FIE Zonal Qualifying Event — Europe | C10: Fencing | D10: X | E10: GLOBAL | F10: 2028-04-02 | G10: 2028-04-30 | H10: CONFIRMED | J10: SCHEDULED | K10: Zonal event · one athlete per NOC per weapon | M10: https://fie.org/ | N10: D.2 | O10: FROM_IOC_DOC | P10: Last-chance event. Open ONLY to NOCs with no athlete qualified for that weapon via team, AOR, or AOR by zone. Runs AFTER ranking closure (1 Apr 2028).
A11: fie-zonal-qualifying-asia-oceania | B11: FIE Zonal Qualifying Event — Asia-Oceania | C11: Fencing | D11: X | E11: GLOBAL | F11: 2028-04-02 | G11: 2028-04-30 | H11: CONFIRMED | J11: SCHEDULED | K11: Zonal event · one athlete per NOC per weapon | M11: https://fie.org/ | N11: D.2 | O11: FROM_IOC_DOC | P11: Last-chance event. Open ONLY to NOCs with no athlete qualified for that weapon via team, AOR, or AOR by zone. Runs AFTER ranking closure (1 Apr 2028).
A12: fie-zonal-qualifying-americas | B12: FIE Zonal Qualifying Event — the Americas | C12: Fencing | D12: X | E12: GLOBAL | F12: 2028-04-02 | G12: 2028-04-30 | H12: CONFIRMED | J12: SCHEDULED | K12: Zonal event · one athlete per NOC per weapon | M12: https://fie.org/ | N12: D.2 | O12: FROM_IOC_DOC | P12: Last-chance event. Open ONLY to NOCs with no athlete qualified for that weapon via team, AOR, or AOR by zone. Runs AFTER ranking closure (1 Apr 2028).
A13: fie-zonal-qualifying-africa | B13: FIE Zonal Qualifying Event — Africa | C13: Fencing | D13: X | E13: GLOBAL | F13: 2028-04-02 | G13: 2028-04-30 | H13: CONFIRMED | J13: SCHEDULED | K13: Zonal event · one athlete per NOC per weapon | M13: https://fie.org/ | N13: D.2 | O13: FROM_IOC_DOC | P13: Last-chance event. Open ONLY to NOCs with no athlete qualified for that weapon via team, AOR, or AOR by zone. Runs AFTER ranking closure (1 Apr 2028).
A14: icc-womens-t20-world-cup-2026 | B14: ICC Women’s T20 World Cup 2026 | C14: Cricket | D14: W | E14: GLOBAL | F14: 2026-06-12 | G14: 2026-07-06 | H14: CONFIRMED | J14: COMPLETE | K14: T20 World Cup · group stage then knockout | M14: https://www.icc-cricket.com/ | N14: D.4, H | O14: FROM_IOC_DOC | P14: Awards the four direct women’s places to the top-standing eligible NOC from each of four continents. Also a T20I event, so its matches feed the women’s ranking — one competition, two roles. Concluded 6 July 2026; verify the four allocated NOCs against ICC’s published confirmation before treating them as settled.
A15: icc-fogqt-men | B15: Final Olympic Global Qualification Tournament — Men | C15: Cricket | D15: M | E15: GLOBAL | H15: TBD | J15: UNANNOUNCED | K15: 8 teams · format TBC | M15: https://www.icc-cricket.com/ | N15: D.3, H | O15: FROM_IOC_DOC | P15: Date and venue TBC. Field of 8 = next eight highest-ranked eligible teams not yet qualified on the ICC Men’s T20I Rankings, allocated 31 Dec 2026. Winner takes the last men’s place. No cap on continental representation at this stage.
A16: icc-fogqt-women | B16: Final Olympic Global Qualification Tournament — Women | C16: Cricket | D16: W | E16: GLOBAL | H16: TBD | J16: UNANNOUNCED | K16: 8 teams · format TBC | M16: https://www.icc-cricket.com/ | N16: D.6, H | O16: FROM_IOC_DOC | P16: Date and venue TBC. Field of 8 = next eight highest-ranked eligible teams not yet qualified on the ICC Women’s T20I Rankings, allocated 1 March 2027. Winner takes the last women’s place. No cap on continental representation.
A17: icc-west-indies-regional-tournament-m | B17: West Indies Nations Regional Tournament — Men | C17: Cricket | D17: M | E17: GLOBAL | H17: TBD | J17: CONDITIONAL | K17: Caribbean NOCs · format TBC, tournament conditional | M17: https://www.icc-cricket.com/ | N17: D.3 | O17: FROM_IOC_DOC | P17: CURRENTLY ON TRACK TO HAPPEN. West Indies sits 7th in the men’s rankings and is inside the eight highest-ranked teams not yet qualified. Decides which Caribbean NOC represents the region at the men’s Olympics Qualifier. Trigger is assessed on the 31 Dec 2026 standings.
A18: icc-west-indies-regional-tournament-w | B18: West Indies Nations Regional Tournament — Women | C18: Cricket | D18: W | E18: GLOBAL | H18: TBD | J18: CONDITIONAL | K18: Caribbean NOCs · format TBC, tournament conditional | M18: https://www.icc-cricket.com/ | N18: D.6 | O18: FROM_IOC_DOC | P18: CURRENTLY ON TRACK TO HAPPEN. West Indies sits 7th and is inside the eight highest-ranked teams not yet qualified, which is the trigger condition. Decides which Caribbean NOC represents the region at the women’s Olympics Qualifier. Still conditional — it is the 1 March 2027 standings that count, not today’s.
A19: uefa-u21-euro-2027 | B19: 2027 UEFA European Under-21 Championship | C19: Football | D19: M | E19: UEFA | F19: 2027-06-01 | G19: 2027-06-30 | H19: APPROXIMATE | I19: Albania / Serbia | J19: SCHEDULED | K19: 16 teams · four groups of four, then knockout | M19: https://www.fifa.com/ | N19: https://en.wikipedia.org/wiki/Football_at_the_2028_Summer_Olympics_%E2%80%93_Men%27s_qualification | O19: CONFLICTING_DATES | P19: 16 teams. Awards 3 Olympic berths to the top 3 ELIGIBLE teams. DATE CONFLICT: Wikipedia’s tournament page gives 17 June – 4 July 2027, Totallympics gives 9–27 June, the qualification table just says June 2027. Verify with UEFA.
A20: uefa-u21-euro-2027-qualifying | B20: 2027 UEFA U21 Championship qualifying | C20: Football | D20: M | E20: UEFA | F20: 2025-06-05 | G20: 2026-10-06 | H20: CONFIRMED | I20: Various | J20: IN_PROGRESS | K20: 51 teams · nine groups, home and away, 12 matchdays | M20: https://www.fifa.com/ | N20: https://en.wikipedia.org/wiki/Football_at_the_2028_Summer_Olympics_%E2%80%93_Men%27s_qualification | O20: FROM_WIKIPEDIA | P20: 51 teams in nine groups (six of six, three of five), home and away, 172 matches. Group stage CLOSES 6 Oct 2026. The nine group winners plus the best runner-up qualify directly; the other eight runners-up drop into play-offs. Decisive matchdays 10–12 fall in a double window: 24–26 Sep, 28 Sep–1 Oct and 5–6 Oct 2026. Individual fixtures not captured — 172 matches were beyond what could be sourced.
A21: concacaf-u20-2026-qualification | B21: 2026 CONCACAF U-20 Championship qualification | C21: Football | D21: M | E21: CONCACAF | F21: 2026-02-23 | G21: 2026-03-04 | H21: CONFIRMED | J21: COMPLETE | K21: 32 teams · 6 groups (two of six, four of five), single round-robin | M21: https://www.fifa.com/ | N21: https://en.wikipedia.org/wiki/Football_at_the_2028_Summer_Olympics_%E2%80%93_Men%27s_qualification | O21: UNCONFIRMED | P21: Hosts: Costa Rica, Curaçao, Nicaragua. 67 matches; the six group winners advanced to the 2026 CONCACAF U-20 Championship. Individual fixtures not captured.
A22: afc-u23-asian-cup-2028 | B22: 2028 AFC U-23 Asian Cup | C22: Football | D22: M | E22: AFC | H22: TBD | J22: UNANNOUNCED | M22: https://www.fifa.com/ | N22: https://en.wikipedia.org/wiki/Football_at_the_2028_Summer_Olympics_%E2%80%93_Men%27s_qualification | O22: FROM_WIKIPEDIA | P22: Awards 2 Olympic berths. Dates, venue and format not announced. As of Feb 2026 only CONCACAF and UEFA had published their men’s processes.
A23: u23-afcon-2027 | B23: 2027 U-23 Africa Cup of Nations | C23: Football | D23: M | E23: CAF | H23: TBD | J23: UNANNOUNCED | M23: https://www.fifa.com/ | N23: https://en.wikipedia.org/wiki/Football_at_the_2028_Summer_Olympics_%E2%80%93_Men%27s_qualification | O23: FROM_WIKIPEDIA | P23: Awards 2 Olympic berths. Dates, venue and format not announced.
A24: conmebol-olympic-qualifying-2028-m | B24: CONMEBOL men’s Olympic qualifying (format TBA) | C24: Football | D24: M | E24: CONMEBOL | H24: TBD | J24: UNANNOUNCED | M24: https://www.fifa.com/ | N24: https://en.wikipedia.org/wiki/Football_at_the_2028_Summer_Olympics_%E2%80%93_Men%27s_qualification | O24: FROM_WIKIPEDIA | P24: Awards 2 Olympic berths. CONMEBOL had not announced its men’s process as of Feb 2026. Placeholder so the 12 berths reconcile.
A25: ofc-olympic-qualifying-2028-m | B25: OFC men’s Olympic qualifying (format TBA) | C25: Football | D25: M | E25: OFC | H25: TBD | J25: UNANNOUNCED | M25: https://www.fifa.com/ | N25: https://en.wikipedia.org/wiki/Football_at_the_2028_Summer_Olympics_%E2%80%93_Men%27s_qualification | O25: FROM_WIKIPEDIA | P25: Awards 1 Olympic berth. Format not announced.
A26: afc-w-oqt-2028 | B26: 2028 AFC Women’s Olympic Qualifying Tournament | C26: Football | D26: W | E26: AFC | F26: 2027-04-19 | G26: 2028-03-04 | H26: CONFIRMED | I26: Multiple | J26: SCHEDULED | K26: 8 teams · two groups of four, league format | M26: https://www.fifa.com/ | N26: https://en.wikipedia.org/wiki/Football_at_the_2028_Summer_Olympics_%E2%80%93_Women%27s_qualification | O26: CONFLICTING_DATES | P26: Field fully known (the eight 2026 Asian Cup quarter-finalists): Australia, North Korea, China, Chinese Taipei, South Korea, Uzbekistan, Japan, Philippines. Group winners qualify for the Olympics; runners-up go to a play-off. 19 Apr 2027 - 4 Mar 2028. Group draw NOT yet made — the field being known is not the draw being made; do not fixture until drawn.
A27: afc-womens-asian-cup-2026 | B27: 2026 AFC Women’s Asian Cup | C27: Football | D27: W | E27: AFC | F27: 2026-03-01 | G27: 2026-03-21 | H27: CONFIRMED | I27: Perth / Gold Coast / Sydney | J27: COMPLETE | M27: https://www.fifa.com/ | N27: https://en.wikipedia.org/wiki/Football_at_the_2028_Summer_Olympics_%E2%80%93_Women%27s_qualification | O27: UNCONFIRMED | P27: Its eight quarter-finalists form the field for the 2028 AFC Women’s Olympic Qualifying Tournament. Reaching the quarter-finals is therefore the real Asian entry point. Dates not captured — fill in from AFC. Japan champions, Australia runners-up, China and South Korea losing semi-finalists. Remaining four quarter-finalists not yet identified.
A28: caf-w-oqt-2028-r1 | B28: 2028 CAF Women’s Olympic Qualifying — Round 1 | C28: Football | D28: W | E28: CAF | F28: 2026-06-01 | G28: 2026-06-09 | H28: CONFIRMED | I28: Multiple | J28: COMPLETE | K28: 6 teams · 3 two-legged ties | M28: https://www.fifa.com/ | N28: https://en.wikipedia.org/wiki/Football_at_the_2028_Summer_Olympics_%E2%80%93_Women%27s_qualification | O28: FROM_WIKIPEDIA | P28: 6 lowest-ranked teams by FIFA ranking in 3 two-legged ties: Comoros v Sudan (30-0 agg), Madagascar and Mauritius v South Sudan and Djibouti in an unsourced order (2-1 and 3-1 agg). Winners: Comoros, Madagascar, Mauritius — all advance to Round 2. 35 nations entered; all ties home-and-away. Round 1 of 5.
A29: caf-w-oqt-2028-r2 | B29: 2028 CAF Women’s Olympic Qualifying — Round 2 | C29: Football | D29: W | E29: CAF | F29: 2026-10-05 | G29: 2026-10-13 | H29: CONFIRMED | I29: Multiple | J29: SCHEDULED | K29: 32 teams · 16 two-legged ties | M29: https://www.fifa.com/ | N29: https://en.wikipedia.org/wiki/Football_at_the_2028_Summer_Olympics_%E2%80%93_Women%27s_qualification | O29: FROM_WIKIPEDIA | P29: 32 teams in 16 ties: the 3 first-round winners join the 29 teams that received byes — the byes include the 3 highest-ranked (Nigeria, South Africa, Ghana). 29 + 3 = 32. 16 winners advance. 35 nations entered; all ties home-and-away. Round 2 of 5. R2 pairings confirmed so far: Comoros v Nigeria. Madagascar and Mauritius face South Africa and Ghana in an unsourced order — full draw not resolved, so R2 stays unfixtured.
A30: caf-w-oqt-2028-r3 | B30: 2028 CAF Women’s Olympic Qualifying — Round 3 | C30: Football | D30: W | E30: CAF | F30: 2027-02-23 | G30: 2027-03-06 | H30: CONFIRMED | I30: Multiple | J30: SCHEDULED | K30: 16 teams · 8 two-legged ties | M30: https://www.fifa.com/ | N30: https://en.wikipedia.org/wiki/Football_at_the_2028_Summer_Olympics_%E2%80%93_Women%27s_qualification | O30: FROM_WIKIPEDIA | P30: 16 teams in 8 ties. 8 winners advance. 35 nations entered; all ties home-and-away. Round 3 of 5.
A31: caf-w-oqt-2028-r4 | B31: 2028 CAF Women’s Olympic Qualifying — Round 4 | C31: Football | D31: W | E31: CAF | F31: 2027-10-04 | G31: 2027-10-12 | H31: CONFIRMED | I31: Multiple | J31: SCHEDULED | K31: 8 teams · 4 two-legged ties | M31: https://www.fifa.com/ | N31: https://en.wikipedia.org/wiki/Football_at_the_2028_Summer_Olympics_%E2%80%93_Women%27s_qualification | O31: FROM_WIKIPEDIA | P31: 8 teams in 4 ties. 4 winners advance. 35 nations entered; all ties home-and-away. Round 4 of 5.
A32: caf-w-oqt-2028-r5 | B32: 2028 CAF Women’s Olympic Qualifying — Round 5 | C32: Football | D32: W | E32: CAF | F32: 2027-11-23 | G32: 2027-12-04 | H32: CONFIRMED | I32: Multiple | J32: SCHEDULED | K32: 4 teams · 2 two-legged ties | M32: https://www.fifa.com/ | N32: https://en.wikipedia.org/wiki/Football_at_the_2028_Summer_Olympics_%E2%80%93_Women%27s_qualification | O32: FROM_WIKIPEDIA | P32: Final 4 teams in 2 ties. The 2 winners take Africa’s Olympic places. 35 nations entered; all ties home-and-away. Round 5 of 5.
A33: concacaf-w-championship-2026 | B33: 2026 CONCACAF W Championship | C33: Football | D33: W | E33: CONCACAF | F33: 2026-11-27 | G33: 2026-12-05 | H33: CONFIRMED | I33: United States | J33: SCHEDULED | K33: Group stage, then semi-finals, third-place play-off and final | M33: https://www.fifa.com/ | N33: https://en.wikipedia.org/wiki/Football_at_the_2028_Summer_Olympics_%E2%80%93_Women%27s_qualification | O33: FROM_WIKIPEDIA | P33: Awards 3 Olympic berths: the two finalists plus the winner of the third-place match. CONDITIONAL VARIANT: if the USA (already in as host) reaches the semi-finals, the three other semi-finalists qualify instead. With the host place that makes 4 CONCACAF teams in total, double its 2024 representation.
A34: copa-america-femenina-2025 | B34: 2025 Copa América Femenina | C34: Football | D34: W | E34: CONMEBOL | F34: 2025-07-11 | G34: 2025-08-02 | H34: CONFIRMED | I34: Ecuador | J34: COMPLETE | K34: Group stage then knockout · concluded | M34: https://www.fifa.com/ | N34: https://en.wikipedia.org/wiki/Football_at_the_2028_Summer_Olympics_%E2%80%93_Women%27s_qualification | O34: FROM_WIKIPEDIA | P34: Brazil and Colombia qualified as finalists — before FIFA had even announced the slot allocation. The third-placed team goes to the AFC–CONMEBOL play-off. South America’s two direct places are settled and cannot change.
A35: ofc-w-oqt-2028 | B35: 2028 OFC Olympic Qualifying Tournament | C35: Football | D35: W | E35: OFC | H35: TBD | J35: UNANNOUNCED | M35: https://www.fifa.com/ | N35: https://en.wikipedia.org/wiki/Football_at_the_2028_Summer_Olympics_%E2%80%93_Women%27s_qualification | O35: FROM_WIKIPEDIA | P35: Awards 1 Olympic berth. Format still unannounced as of May 2026.
A36: uefa-wnl-2027 | B36: 2027 UEFA Women’s Nations League | C36: Football | D36: W | E36: UEFA | F36: 2027-03-01 | G36: 2027-11-30 | H36: APPROXIMATE | I36: Various | J36: SCHEDULED | M36: https://www.fifa.com/ | N36: https://en.wikipedia.org/wiki/Football_at_the_2028_Summer_Olympics_%E2%80%93_Women%27s_qualification | O36: UNCONFIRMED_MECHANISM | P36: Awards UEFA’s 4 Olympic berths (allocated 17 Dec 2025). League phase Mar–Jun 2027, finals Oct–Nov 2027. MECHANISM UNCONFIRMED: in the 2024 cycle the Nations League Finals — contested by the four League A group winners — decided the two Olympic places. Whether all four finalists now qualify, or the Finals are played off, is not confirmed in the sources checked.
A37: uefa-womens-european-qualifiers-2026 | B37: 2026 UEFA Women’s European Qualifiers | C37: Football | D37: W | E37: UEFA | F37: 2026-03-03 | G37: 2026-12-05 | H37: CONFIRMED | I37: Various | J37: IN_PROGRESS | M37: https://www.fifa.com/ | N37: https://en.wikipedia.org/wiki/Football_at_the_2028_Summer_Olympics_%E2%80%93_Women%27s_qualification | O37: FROM_WIKIPEDIA | P37: Primarily 2027 World Cup qualifying, but its final league rankings set the League A/B/C composition of the 2027 Nations League — and only League A group winners reach the Nations League Finals. Being in League A is therefore a precondition for the European Olympic route. An indirect qualifier two hops out.
A38: afc-conmebol-playoff-w | B38: AFC–CONMEBOL play-off | C38: Football | D38: W | E38: GLOBAL | H38: TBD | J38: UNANNOUNCED | K38: 2 teams · inter-confederation play-off | M38: https://www.fifa.com/ | N38: https://en.wikipedia.org/wiki/Football_at_the_2028_Summer_Olympics_%E2%80%93_Women%27s_qualification | O38: FROM_WIKIPEDIA | P38: Single berth decided between one AFC team and one CONMEBOL team. Announced by FIFA in Dec 2025 when both confederations were given 2.5 slots. Dates and format TBC.
A39: fiba-womens-afrobasket-2027 | B39: FIBA Women’s AfroBasket 2027 | C39: Basketball | D39: W | E39: FIBA Africa | F39: 2027-07-23 | G39: 2027-08-01 | H39: APPROXIMATE | J39: SCHEDULED | K39: Continental cup · group stage then knockout | M39: https://www.fiba.basketball/ | N39: D, G | O39: FROM_IOC_DOC | P39: The two best classified teams enter the FWOQT. Dates marked subject to change in the IOC document.
A40: fwbwc-qualifying-tournaments-2026 | B40: FIBA Women’s Basketball World Cup Qualifying Tournaments 2026 | C40: Basketball | D40: W | E40: GLOBAL | F40: 2026-03-11 | G40: 2026-03-17 | H40: CONFIRMED | J40: COMPLETE | K40: 24 teams · four tournaments of six, single round-robin | M40: https://www.fiba.basketball/ | N40: D, G | O40: UNCONFIRMED | P40: Hosts: Wuhan (China), Lyon-Villeurbanne (France), San Juan (Puerto Rico), Istanbul (Türkiye). 60 games, 11 World Cup places. Split point of the whole women's pathway: qualifiers went to the FWBWC 2026, the eight that did not went to the FWOPQT. Individual fixtures not captured.
...

Sheet Links
A1: link_id | B1: from_id | C1: from_type | D1: to_id | E1: to_type | F1: relationship | G1: berths | H1: qualifiers | I1: criterion | J1: qualifiers_note | K1: entry_condition | L1: berth_math | M1: eligibility_note | N1: cascade_order | O1: gate_ranking_id | P1: source_ref | Q1: confidence | R1: notes | S1: cut_line_id | T1: check
A2: fen-001 | B2: fie-senior-team-world-cup | C2: COMPETITION | D2: fie-senior-team-ranking | E2: RANKING | F2: RANKING_POINTS | I2: Awards points to the Senior Team Ranking | N2: 0 | P2: D.1 | Q2: FROM_IOC_DOC | T2: =IF(AND(COUNTIF(Competitions!A:A,B2)+COUNTIF(Ranking_Systems!A:A,B2)+COUNTIF(Olympic_Events!A:A,B2)+IF(OR(B2="HOST_USA",B2="TRIPARTITE"),1,0)>0,COUNTIF(Competitions!A:A,D2)+COUNTIF(Ranking_Systems!A:A,D2)+COUNTIF(Olympic_Events!A:A,D2)>0),"OK","BROKEN") -> OK
A3: fen-002 | B3: fie-senior-team-world-championships | C3: COMPETITION | D3: fie-senior-team-ranking | E3: RANKING | F3: RANKING_POINTS | I3: Awards points to the Senior Team Ranking | N3: 0 | P3: D.1 | Q3: FROM_IOC_DOC | T3: =IF(AND(COUNTIF(Competitions!A:A,B3)+COUNTIF(Ranking_Systems!A:A,B3)+COUNTIF(Olympic_Events!A:A,B3)+IF(OR(B3="HOST_USA",B3="TRIPARTITE"),1,0)>0,COUNTIF(Competitions!A:A,D3)+COUNTIF(Ranking_Systems!A:A,D3)+COUNTIF(Olympic_Events!A:A,D3)>0),"OK","BROKEN") -> OK
A4: fen-003 | B4: fie-senior-team-continental-championships | C4: COMPETITION | D4: fie-senior-team-ranking | E4: RANKING | F4: RANKING_POINTS | I4: Awards points to the Senior Team Ranking | N4: 0 | P4: D.1 | Q4: FROM_IOC_DOC | T4: =IF(AND(COUNTIF(Competitions!A:A,B4)+COUNTIF(Ranking_Systems!A:A,B4)+COUNTIF(Olympic_Events!A:A,B4)+IF(OR(B4="HOST_USA",B4="TRIPARTITE"),1,0)>0,COUNTIF(Competitions!A:A,D4)+COUNTIF(Ranking_Systems!A:A,D4)+COUNTIF(Olympic_Events!A:A,D4)>0),"OK","BROKEN") -> OK
A5: fen-004 | B5: fie-individual-grand-prix | C5: COMPETITION | D5: fie-individual-senior-aor | E5: RANKING | F5: RANKING_POINTS | I5: Awards points to the Individual Official Ranking (AOR base) | N5: 0 | P5: D.2 | Q5: FROM_IOC_DOC | T5: =IF(AND(COUNTIF(Competitions!A:A,B5)+COUNTIF(Ranking_Systems!A:A,B5)+COUNTIF(Olympic_Events!A:A,B5)+IF(OR(B5="HOST_USA",B5="TRIPARTITE"),1,0)>0,COUNTIF(Competitions!A:A,D5)+COUNTIF(Ranking_Systems!A:A,D5)+COUNTIF(Olympic_Events!A:A,D5)>0),"OK","BROKEN") -> OK
A6: fen-005 | B6: fie-individual-senior-world-cup | C6: COMPETITION | D6: fie-individual-senior-aor | E6: RANKING | F6: RANKING_POINTS | I6: Awards points to the Individual Official Ranking (AOR base) | N6: 0 | P6: D.2 | Q6: FROM_IOC_DOC | T6: =IF(AND(COUNTIF(Competitions!A:A,B6)+COUNTIF(Ranking_Systems!A:A,B6)+COUNTIF(Olympic_Events!A:A,B6)+IF(OR(B6="HOST_USA",B6="TRIPARTITE"),1,0)>0,COUNTIF(Competitions!A:A,D6)+COUNTIF(Ranking_Systems!A:A,D6)+COUNTIF(Olympic_Events!A:A,D6)>0),"OK","BROKEN") -> OK
A7: fen-006 | B7: fie-satellite-competitions | C7: COMPETITION | D7: fie-individual-senior-aor | E7: RANKING | F7: RANKING_POINTS | I7: Awards points to the Individual Official Ranking (AOR base) | N7: 0 | P7: D.2 | Q7: FROM_IOC_DOC | T7: =IF(AND(COUNTIF(Competitions!A:A,B7)+COUNTIF(Ranking_Systems!A:A,B7)+COUNTIF(Olympic_Events!A:A,B7)+IF(OR(B7="HOST_USA",B7="TRIPARTITE"),1,0)>0,COUNTIF(Competitions!A:A,D7)+COUNTIF(Ranking_Systems!A:A,D7)+COUNTIF(Olympic_Events!A:A,D7)>0),"OK","BROKEN") -> OK
A8: fen-007 | B8: fie-individual-senior-world-championships | C8: COMPETITION | D8: fie-individual-senior-aor | E8: RANKING | F8: RANKING_POINTS | I8: Awards points to the Individual Official Ranking (AOR base) | N8: 0 | P8: D.2 | Q8: FROM_IOC_DOC | T8: =IF(AND(COUNTIF(Competitions!A:A,B8)+COUNTIF(Ranking_Systems!A:A,B8)+COUNTIF(Olympic_Events!A:A,B8)+IF(OR(B8="HOST_USA",B8="TRIPARTITE"),1,0)>0,COUNTIF(Competitions!A:A,D8)+COUNTIF(Ranking_Systems!A:A,D8)+COUNTIF(Olympic_Events!A:A,D8)>0),"OK","BROKEN") -> OK
A9: fen-008 | B9: fie-individual-senior-continental-championships | C9: COMPETITION | D9: fie-individual-senior-aor | E9: RANKING | F9: RANKING_POINTS | I9: Awards points to the Individual Official Ranking (AOR base) | N9: 0 | P9: D.2 | Q9: FROM_IOC_DOC | T9: =IF(AND(COUNTIF(Competitions!A:A,B9)+COUNTIF(Ranking_Systems!A:A,B9)+COUNTIF(Olympic_Events!A:A,B9)+IF(OR(B9="HOST_USA",B9="TRIPARTITE"),1,0)>0,COUNTIF(Competitions!A:A,D9)+COUNTIF(Ranking_Systems!A:A,D9)+COUNTIF(Olympic_Events!A:A,D9)>0),"OK","BROKEN") -> OK
A10: fen-009 | B10: fie-senior-team-ranking | C10: RANKING | D10: la28-fencing-team-foil-m | E10: OLYMPIC_EVENT | F10: RANKING_CUTOFF | G10: 4 | I10: Top 4 teams for this weapon in the FIE Senior Team Ranking of 1 Apr 2028, any zone | N10: 10 | P10: D.1 | Q10: FROM_IOC_DOC | T10: =IF(AND(COUNTIF(Competitions!A:A,B10)+COUNTIF(Ranking_Systems!A:A,B10)+COUNTIF(Olympic_Events!A:A,B10)+IF(OR(B10="HOST_USA",B10="TRIPARTITE"),1,0)>0,COUNTIF(Competitions!A:A,D10)+COUNTIF(Ranking_Systems!A:A,D10)+COUNTIF(Olympic_Events!A:A,D10)>0),"OK","BROKEN") -> OK
A11: fen-010 | B11: fie-senior-team-ranking | C11: RANKING | D11: la28-fencing-team-foil-m | E11: OLYMPIC_EVENT | F11: RANKING_CUTOFF_BY_ZONE | G11: 4 | I11: Highest-ranked team from each of the 4 FIE zones among ranks 5–24 | M11: If a zone has no team in ranks 5–24, the place goes to the next highest-ranked team overall, irrespective of zone. | N11: 20 | P11: D.1 | Q11: FROM_IOC_DOC | T11: =IF(AND(COUNTIF(Competitions!A:A,B11)+COUNTIF(Ranking_Systems!A:A,B11)+COUNTIF(Olympic_Events!A:A,B11)+IF(OR(B11="HOST_USA",B11="TRIPARTITE"),1,0)>0,COUNTIF(Competitions!A:A,D11)+COUNTIF(Ranking_Systems!A:A,D11)+COUNTIF(Olympic_Events!A:A,D11)>0),"OK","BROKEN") -> OK
A12: fen-011 | B12: fie-individual-senior-aor | C12: RANKING | D12: la28-fencing-ind-foil-m | E12: OLYMPIC_EVENT | F12: RANKING_CUTOFF | G12: 2 | I12: Top 2 eligible athletes in the Individual Senior AOR | L12: 10 individual places per weapon, but the 24 team-qualified athletes also compete in the individual event without holding one of these 10. The individual field is 34–37 while the individual quota is 10. | M12: Max 1 athlete per NOC per weapon. AOR already excludes NOCs qualified via team. | N12: 30 | P12: D.2 | Q12: FROM_IOC_DOC | T12: =IF(AND(COUNTIF(Competitions!A:A,B12)+COUNTIF(Ranking_Systems!A:A,B12)+COUNTIF(Olympic_Events!A:A,B12)+IF(OR(B12="HOST_USA",B12="TRIPARTITE"),1,0)>0,COUNTIF(Competitions!A:A,D12)+COUNTIF(Ranking_Systems!A:A,D12)+COUNTIF(Olympic_Events!A:A,D12)>0),"OK","BROKEN") -> OK
A13: fen-012 | B13: fie-individual-senior-aor | C13: RANKING | D13: la28-fencing-ind-foil-m | E13: OLYMPIC_EVENT | F13: RANKING_CUTOFF_BY_ZONE | G13: 4 | I13: Highest-ranked eligible athlete from each of the 4 zones in the AOR by zone | K13: Only if your NOC has NOT already qualified in this weapon at an earlier cascade stage. | L13: 10 individual places per weapon, but the 24 team-qualified athletes also compete in the individual event without holding one of these 10. The individual field is 34–37 while the individual quota is 10. | M13: Open ONLY to NOCs with no athlete qualified for this weapon via team qualification or the Individual Senior AOR. Max 1 per NOC per weapon. | N13: 40 | P13: D.2 | Q13: FROM_IOC_DOC | T13: =IF(AND(COUNTIF(Competitions!A:A,B13)+COUNTIF(Ranking_Systems!A:A,B13)+COUNTIF(Olympic_Events!A:A,B13)+IF(OR(B13="HOST_USA",B13="TRIPARTITE"),1,0)>0,COUNTIF(Competitions!A:A,D13)+COUNTIF(Ranking_Systems!A:A,D13)+COUNTIF(Olympic_Events!A:A,D13)>0),"OK","BROKEN") -> OK
A14: fen-013 | B14: fie-zonal-qualifying-europe | C14: COMPETITION | D14: la28-fencing-ind-foil-m | E14: OLYMPIC_EVENT | F14: PLACING_ELIGIBLE | G14: 1 | I14: Winner from the Europe zonal qualifying event | K14: Only if your NOC has NOT already qualified in this weapon at an earlier cascade stage. | M14: Open ONLY to NOCs with no athlete qualified for this weapon via team qualification, the Individual Senior AOR, or the AOR by zone. Max 1 per NOC per weapon. | N14: 50 | P14: D.2 | Q14: FROM_IOC_DOC | T14: =IF(AND(COUNTIF(Competitions!A:A,B14)+COUNTIF(Ranking_Systems!A:A,B14)+COUNTIF(Olympic_Events!A:A,B14)+IF(OR(B14="HOST_USA",B14="TRIPARTITE"),1,0)>0,COUNTIF(Competitions!A:A,D14)+COUNTIF(Ranking_Systems!A:A,D14)+COUNTIF(Olympic_Events!A:A,D14)>0),"OK","BROKEN") -> OK
A15: fen-014 | B15: fie-zonal-qualifying-asia-oceania | C15: COMPETITION | D15: la28-fencing-ind-foil-m | E15: OLYMPIC_EVENT | F15: PLACING_ELIGIBLE | G15: 1 | I15: Winner from the Asia-Oceania zonal qualifying event | K15: Only if your NOC has NOT already qualified in this weapon at an earlier cascade stage. | M15: Open ONLY to NOCs with no athlete qualified for this weapon via team qualification, the Individual Senior AOR, or the AOR by zone. Max 1 per NOC per weapon. | N15: 50 | P15: D.2 | Q15: FROM_IOC_DOC | T15: =IF(AND(COUNTIF(Competitions!A:A,B15)+COUNTIF(Ranking_Systems!A:A,B15)+COUNTIF(Olympic_Events!A:A,B15)+IF(OR(B15="HOST_USA",B15="TRIPARTITE"),1,0)>0,COUNTIF(Competitions!A:A,D15)+COUNTIF(Ranking_Systems!A:A,D15)+COUNTIF(Olympic_Events!A:A,D15)>0),"OK","BROKEN") -> OK
A16: fen-015 | B16: fie-zonal-qualifying-americas | C16: COMPETITION | D16: la28-fencing-ind-foil-m | E16: OLYMPIC_EVENT | F16: PLACING_ELIGIBLE | G16: 1 | I16: Winner from the the Americas zonal qualifying event | K16: Only if your NOC has NOT already qualified in this weapon at an earlier cascade stage. | M16: Open ONLY to NOCs with no athlete qualified for this weapon via team qualification, the Individual Senior AOR, or the AOR by zone. Max 1 per NOC per weapon. | N16: 50 | P16: D.2 | Q16: FROM_IOC_DOC | T16: =IF(AND(COUNTIF(Competitions!A:A,B16)+COUNTIF(Ranking_Systems!A:A,B16)+COUNTIF(Olympic_Events!A:A,B16)+IF(OR(B16="HOST_USA",B16="TRIPARTITE"),1,0)>0,COUNTIF(Competitions!A:A,D16)+COUNTIF(Ranking_Systems!A:A,D16)+COUNTIF(Olympic_Events!A:A,D16)>0),"OK","BROKEN") -> OK
A17: fen-016 | B17: fie-zonal-qualifying-africa | C17: COMPETITION | D17: la28-fencing-ind-foil-m | E17: OLYMPIC_EVENT | F17: PLACING_ELIGIBLE | G17: 1 | I17: Winner from the Africa zonal qualifying event | K17: Only if your NOC has NOT already qualified in this weapon at an earlier cascade stage. | M17: Open ONLY to NOCs with no athlete qualified for this weapon via team qualification, the Individual Senior AOR, or the AOR by zone. Max 1 per NOC per weapon. | N17: 50 | P17: D.2 | Q17: FROM_IOC_DOC | T17: =IF(AND(COUNTIF(Competitions!A:A,B17)+COUNTIF(Ranking_Systems!A:A,B17)+COUNTIF(Olympic_Events!A:A,B17)+IF(OR(B17="HOST_USA",B17="TRIPARTITE"),1,0)>0,COUNTIF(Competitions!A:A,D17)+COUNTIF(Ranking_Systems!A:A,D17)+COUNTIF(Olympic_Events!A:A,D17)>0),"OK","BROKEN") -> OK
A18: fen-017 | B18: fie-senior-team-ranking | C18: RANKING | D18: la28-fencing-team-epee-m | E18: OLYMPIC_EVENT | F18: RANKING_CUTOFF | G18: 4 | I18: Top 4 teams for this weapon in the FIE Senior Team Ranking of 1 Apr 2028, any zone | N18: 10 | P18: D.1 | Q18: FROM_IOC_DOC | T18: =IF(AND(COUNTIF(Competitions!A:A,B18)+COUNTIF(Ranking_Systems!A:A,B18)+COUNTIF(Olympic_Events!A:A,B18)+IF(OR(B18="HOST_USA",B18="TRIPARTITE"),1,0)>0,COUNTIF(Competitions!A:A,D18)+COUNTIF(Ranking_Systems!A:A,D18)+COUNTIF(Olympic_Events!A:A,D18)>0),"OK","BROKEN") -> OK
A19: fen-018 | B19: fie-senior-team-ranking | C19: RANKING | D19: la28-fencing-team-epee-m | E19: OLYMPIC_EVENT | F19: RANKING_CUTOFF_BY_ZONE | G19: 4 | I19: Highest-ranked team from each of the 4 FIE zones among ranks 5–24 | M19: If a zone has no team in ranks 5–24, the place goes to the next highest-ranked team overall, irrespective of zone. | N19: 20 | P19: D.1 | Q19: FROM_IOC_DOC | T19: =IF(AND(COUNTIF(Competitions!A:A,B19)+COUNTIF(Ranking_Systems!A:A,B19)+COUNTIF(Olympic_Events!A:A,B19)+IF(OR(B19="HOST_USA",B19="TRIPARTITE"),1,0)>0,COUNTIF(Competitions!A:A,D19)+COUNTIF(Ranking_Systems!A:A,D19)+COUNTIF(Olympic_Events!A:A,D19)>0),"OK","BROKEN") -> OK
A20: fen-019 | B20: fie-individual-senior-aor | C20: RANKING | D20: la28-fencing-ind-epee-m | E20: OLYMPIC_EVENT | F20: RANKING_CUTOFF | G20: 2 | I20: Top 2 eligible athletes in the Individual Senior AOR | L20: 10 individual places per weapon, but the 24 team-qualified athletes also compete in the individual event without holding one of these 10. The individual field is 34–37 while the individual quota is 10. | M20: Max 1 athlete per NOC per weapon. AOR already excludes NOCs qualified via team. | N20: 30 | P20: D.2 | Q20: FROM_IOC_DOC | T20: =IF(AND(COUNTIF(Competitions!A:A,B20)+COUNTIF(Ranking_Systems!A:A,B20)+COUNTIF(Olympic_Events!A:A,B20)+IF(OR(B20="HOST_USA",B20="TRIPARTITE"),1,0)>0,COUNTIF(Competitions!A:A,D20)+COUNTIF(Ranking_Systems!A:A,D20)+COUNTIF(Olympic_Events!A:A,D20)>0),"OK","BROKEN") -> OK
A21: fen-020 | B21: fie-individual-senior-aor | C21: RANKING | D21: la28-fencing-ind-epee-m | E21: OLYMPIC_EVENT | F21: RANKING_CUTOFF_BY_ZONE | G21: 4 | I21: Highest-ranked eligible athlete from each of the 4 zones in the AOR by zone | K21: Only if your NOC has NOT already qualified in this weapon at an earlier cascade stage. | L21: 10 individual places per weapon, but the 24 team-qualified athletes also compete in the individual event without holding one of these 10. The individual field is 34–37 while the individual quota is 10. | M21: Open ONLY to NOCs with no athlete qualified for this weapon via team qualification or the Individual Senior AOR. Max 1 per NOC per weapon. | N21: 40 | P21: D.2 | Q21: FROM_IOC_DOC | T21: =IF(AND(COUNTIF(Competitions!A:A,B21)+COUNTIF(Ranking_Systems!A:A,B21)+COUNTIF(Olympic_Events!A:A,B21)+IF(OR(B21="HOST_USA",B21="TRIPARTITE"),1,0)>0,COUNTIF(Competitions!A:A,D21)+COUNTIF(Ranking_Systems!A:A,D21)+COUNTIF(Olympic_Events!A:A,D21)>0),"OK","BROKEN") -> OK
A22: fen-021 | B22: fie-zonal-qualifying-europe | C22: COMPETITION | D22: la28-fencing-ind-epee-m | E22: OLYMPIC_EVENT | F22: PLACING_ELIGIBLE | G22: 1 | I22: Winner from the Europe zonal qualifying event | K22: Only if your NOC has NOT already qualified in this weapon at an earlier cascade stage. | M22: Open ONLY to NOCs with no athlete qualified for this weapon via team qualification, the Individual Senior AOR, or the AOR by zone. Max 1 per NOC per weapon. | N22: 50 | P22: D.2 | Q22: FROM_IOC_DOC | T22: =IF(AND(COUNTIF(Competitions!A:A,B22)+COUNTIF(Ranking_Systems!A:A,B22)+COUNTIF(Olympic_Events!A:A,B22)+IF(OR(B22="HOST_USA",B22="TRIPARTITE"),1,0)>0,COUNTIF(Competitions!A:A,D22)+COUNTIF(Ranking_Systems!A:A,D22)+COUNTIF(Olympic_Events!A:A,D22)>0),"OK","BROKEN") -> OK
A23: fen-022 | B23: fie-zonal-qualifying-asia-oceania | C23: COMPETITION | D23: la28-fencing-ind-epee-m | E23: OLYMPIC_EVENT | F23: PLACING_ELIGIBLE | G23: 1 | I23: Winner from the Asia-Oceania zonal qualifying event | K23: Only if your NOC has NOT already qualified in this weapon at an earlier cascade stage. | M23: Open ONLY to NOCs with no athlete qualified for this weapon via team qualification, the Individual Senior AOR, or the AOR by zone. Max 1 per NOC per weapon. | N23: 50 | P23: D.2 | Q23: FROM_IOC_DOC | T23: =IF(AND(COUNTIF(Competitions!A:A,B23)+COUNTIF(Ranking_Systems!A:A,B23)+COUNTIF(Olympic_Events!A:A,B23)+IF(OR(B23="HOST_USA",B23="TRIPARTITE"),1,0)>0,COUNTIF(Competitions!A:A,D23)+COUNTIF(Ranking_Systems!A:A,D23)+COUNTIF(Olympic_Events!A:A,D23)>0),"OK","BROKEN") -> OK
A24: fen-023 | B24: fie-zonal-qualifying-americas | C24: COMPETITION | D24: la28-fencing-ind-epee-m | E24: OLYMPIC_EVENT | F24: PLACING_ELIGIBLE | G24: 1 | I24: Winner from the the Americas zonal qualifying event | K24: Only if your NOC has NOT already qualified in this weapon at an earlier cascade stage. | M24: Open ONLY to NOCs with no athlete qualified for this weapon via team qualification, the Individual Senior AOR, or the AOR by zone. Max 1 per NOC per weapon. | N24: 50 | P24: D.2 | Q24: FROM_IOC_DOC | T24: =IF(AND(COUNTIF(Competitions!A:A,B24)+COUNTIF(Ranking_Systems!A:A,B24)+COUNTIF(Olympic_Events!A:A,B24)+IF(OR(B24="HOST_USA",B24="TRIPARTITE"),1,0)>0,COUNTIF(Competitions!A:A,D24)+COUNTIF(Ranking_Systems!A:A,D24)+COUNTIF(Olympic_Events!A:A,D24)>0),"OK","BROKEN") -> OK
A25: fen-024 | B25: fie-zonal-qualifying-africa | C25: COMPETITION | D25: la28-fencing-ind-epee-m | E25: OLYMPIC_EVENT | F25: PLACING_ELIGIBLE | G25: 1 | I25: Winner from the Africa zonal qualifying event | K25: Only if your NOC has NOT already qualified in this weapon at an earlier cascade stage. | M25: Open ONLY to NOCs with no athlete qualified for this weapon via team qualification, the Individual Senior AOR, or the AOR by zone. Max 1 per NOC per weapon. | N25: 50 | P25: D.2 | Q25: FROM_IOC_DOC | T25: =IF(AND(COUNTIF(Competitions!A:A,B25)+COUNTIF(Ranking_Systems!A:A,B25)+COUNTIF(Olympic_Events!A:A,B25)+IF(OR(B25="HOST_USA",B25="TRIPARTITE"),1,0)>0,COUNTIF(Competitions!A:A,D25)+COUNTIF(Ranking_Systems!A:A,D25)+COUNTIF(Olympic_Events!A:A,D25)>0),"OK","BROKEN") -> OK
A26: fen-025 | B26: fie-senior-team-ranking | C26: RANKING | D26: la28-fencing-team-sabre-m | E26: OLYMPIC_EVENT | F26: RANKING_CUTOFF | G26: 4 | I26: Top 4 teams for this weapon in the FIE Senior Team Ranking of 1 Apr 2028, any zone | N26: 10 | P26: D.1 | Q26: FROM_IOC_DOC | T26: =IF(AND(COUNTIF(Competitions!A:A,B26)+COUNTIF(Ranking_Systems!A:A,B26)+COUNTIF(Olympic_Events!A:A,B26)+IF(OR(B26="HOST_USA",B26="TRIPARTITE"),1,0)>0,COUNTIF(Competitions!A:A,D26)+COUNTIF(Ranking_Systems!A:A,D26)+COUNTIF(Olympic_Events!A:A,D26)>0),"OK","BROKEN") -> OK
A27: fen-026 | B27: fie-senior-team-ranking | C27: RANKING | D27: la28-fencing-team-sabre-m | E27: OLYMPIC_EVENT | F27: RANKING_CUTOFF_BY_ZONE | G27: 4 | I27: Highest-ranked team from each of the 4 FIE zones among ranks 5–24 | M27: If a zone has no team in ranks 5–24, the place goes to the next highest-ranked team overall, irrespective of zone. | N27: 20 | P27: D.1 | Q27: FROM_IOC_DOC | T27: =IF(AND(COUNTIF(Competitions!A:A,B27)+COUNTIF(Ranking_Systems!A:A,B27)+COUNTIF(Olympic_Events!A:A,B27)+IF(OR(B27="HOST_USA",B27="TRIPARTITE"),1,0)>0,COUNTIF(Competitions!A:A,D27)+COUNTIF(Ranking_Systems!A:A,D27)+COUNTIF(Olympic_Events!A:A,D27)>0),"OK","BROKEN") -> OK
A28: fen-027 | B28: fie-individual-senior-aor | C28: RANKING | D28: la28-fencing-ind-sabre-m | E28: OLYMPIC_EVENT | F28: RANKING_CUTOFF | G28: 2 | I28: Top 2 eligible athletes in the Individual Senior AOR | L28: 10 individual places per weapon, but the 24 team-qualified athletes also compete in the individual event without holding one of these 10. The individual field is 34–37 while the individual quota is 10. | M28: Max 1 athlete per NOC per weapon. AOR already excludes NOCs qualified via team. | N28: 30 | P28: D.2 | Q28: FROM_IOC_DOC | T28: =IF(AND(COUNTIF(Competitions!A:A,B28)+COUNTIF(Ranking_Systems!A:A,B28)+COUNTIF(Olympic_Events!A:A,B28)+IF(OR(B28="HOST_USA",B28="TRIPARTITE"),1,0)>0,COUNTIF(Competitions!A:A,D28)+COUNTIF(Ranking_Systems!A:A,D28)+COUNTIF(Olympic_Events!A:A,D28)>0),"OK","BROKEN") -> OK
A29: fen-028 | B29: fie-individual-senior-aor | C29: RANKING | D29: la28-fencing-ind-sabre-m | E29: OLYMPIC_EVENT | F29: RANKING_CUTOFF_BY_ZONE | G29: 4 | I29: Highest-ranked eligible athlete from each of the 4 zones in the AOR by zone | K29: Only if your NOC has NOT already qualified in this weapon at an earlier cascade stage. | L29: 10 individual places per weapon, but the 24 team-qualified athletes also compete in the individual event without holding one of these 10. The individual field is 34–37 while the individual quota is 10. | M29: Open ONLY to NOCs with no athlete qualified for this weapon via team qualification or the Individual Senior AOR. Max 1 per NOC per weapon. | N29: 40 | P29: D.2 | Q29: FROM_IOC_DOC | T29: =IF(AND(COUNTIF(Competitions!A:A,B29)+COUNTIF(Ranking_Systems!A:A,B29)+COUNTIF(Olympic_Events!A:A,B29)+IF(OR(B29="HOST_USA",B29="TRIPARTITE"),1,0)>0,COUNTIF(Competitions!A:A,D29)+COUNTIF(Ranking_Systems!A:A,D29)+COUNTIF(Olympic_Events!A:A,D29)>0),"OK","BROKEN") -> OK
A30: fen-029 | B30: fie-zonal-qualifying-europe | C30: COMPETITION | D30: la28-fencing-ind-sabre-m | E30: OLYMPIC_EVENT | F30: PLACING_ELIGIBLE | G30: 1 | I30: Winner from the Europe zonal qualifying event | K30: Only if your NOC has NOT already qualified in this weapon at an earlier cascade stage. | M30: Open ONLY to NOCs with no athlete qualified for this weapon via team qualification, the Individual Senior AOR, or the AOR by zone. Max 1 per NOC per weapon. | N30: 50 | P30: D.2 | Q30: FROM_IOC_DOC | T30: =IF(AND(COUNTIF(Competitions!A:A,B30)+COUNTIF(Ranking_Systems!A:A,B30)+COUNTIF(Olympic_Events!A:A,B30)+IF(OR(B30="HOST_USA",B30="TRIPARTITE"),1,0)>0,COUNTIF(Competitions!A:A,D30)+COUNTIF(Ranking_Systems!A:A,D30)+COUNTIF(Olympic_Events!A:A,D30)>0),"OK","BROKEN") -> OK
A31: fen-030 | B31: fie-zonal-qualifying-asia-oceania | C31: COMPETITION | D31: la28-fencing-ind-sabre-m | E31: OLYMPIC_EVENT | F31: PLACING_ELIGIBLE | G31: 1 | I31: Winner from the Asia-Oceania zonal qualifying event | K31: Only if your NOC has NOT already qualified in this weapon at an earlier cascade stage. | M31: Open ONLY to NOCs with no athlete qualified for this weapon via team qualification, the Individual Senior AOR, or the AOR by zone. Max 1 per NOC per weapon. | N31: 50 | P31: D.2 | Q31: FROM_IOC_DOC | T31: =IF(AND(COUNTIF(Competitions!A:A,B31)+COUNTIF(Ranking_Systems!A:A,B31)+COUNTIF(Olympic_Events!A:A,B31)+IF(OR(B31="HOST_USA",B31="TRIPARTITE"),1,0)>0,COUNTIF(Competitions!A:A,D31)+COUNTIF(Ranking_Systems!A:A,D31)+COUNTIF(Olympic_Events!A:A,D31)>0),"OK","BROKEN") -> OK
A32: fen-031 | B32: fie-zonal-qualifying-americas | C32: COMPETITION | D32: la28-fencing-ind-sabre-m | E32: OLYMPIC_EVENT | F32: PLACING_ELIGIBLE | G32: 1 | I32: Winner from the the Americas zonal qualifying event | K32: Only if your NOC has NOT already qualified in this weapon at an earlier cascade stage. | M32: Open ONLY to NOCs with no athlete qualified for this weapon via team qualification, the Individual Senior AOR, or the AOR by zone. Max 1 per NOC per weapon. | N32: 50 | P32: D.2 | Q32: FROM_IOC_DOC | T32: =IF(AND(COUNTIF(Competitions!A:A,B32)+COUNTIF(Ranking_Systems!A:A,B32)+COUNTIF(Olympic_Events!A:A,B32)+IF(OR(B32="HOST_USA",B32="TRIPARTITE"),1,0)>0,COUNTIF(Competitions!A:A,D32)+COUNTIF(Ranking_Systems!A:A,D32)+COUNTIF(Olympic_Events!A:A,D32)>0),"OK","BROKEN") -> OK
A33: fen-032 | B33: fie-zonal-qualifying-africa | C33: COMPETITION | D33: la28-fencing-ind-sabre-m | E33: OLYMPIC_EVENT | F33: PLACING_ELIGIBLE | G33: 1 | I33: Winner from the Africa zonal qualifying event | K33: Only if your NOC has NOT already qualified in this weapon at an earlier cascade stage. | M33: Open ONLY to NOCs with no athlete qualified for this weapon via team qualification, the Individual Senior AOR, or the AOR by zone. Max 1 per NOC per weapon. | N33: 50 | P33: D.2 | Q33: FROM_IOC_DOC | T33: =IF(AND(COUNTIF(Competitions!A:A,B33)+COUNTIF(Ranking_Systems!A:A,B33)+COUNTIF(Olympic_Events!A:A,B33)+IF(OR(B33="HOST_USA",B33="TRIPARTITE"),1,0)>0,COUNTIF(Competitions!A:A,D33)+COUNTIF(Ranking_Systems!A:A,D33)+COUNTIF(Olympic_Events!A:A,D33)>0),"OK","BROKEN") -> OK
A34: fen-033 | B34: fie-senior-team-ranking | C34: RANKING | D34: la28-fencing-team-foil-w | E34: OLYMPIC_EVENT | F34: RANKING_CUTOFF | G34: 4 | I34: Top 4 teams for this weapon in the FIE Senior Team Ranking of 1 Apr 2028, any zone | N34: 10 | P34: D.1 | Q34: FROM_IOC_DOC | T34: =IF(AND(COUNTIF(Competitions!A:A,B34)+COUNTIF(Ranking_Systems!A:A,B34)+COUNTIF(Olympic_Events!A:A,B34)+IF(OR(B34="HOST_USA",B34="TRIPARTITE"),1,0)>0,COUNTIF(Competitions!A:A,D34)+COUNTIF(Ranking_Systems!A:A,D34)+COUNTIF(Olympic_Events!A:A,D34)>0),"OK","BROKEN") -> OK
A35: fen-034 | B35: fie-senior-team-ranking | C35: RANKING | D35: la28-fencing-team-foil-w | E35: OLYMPIC_EVENT | F35: RANKING_CUTOFF_BY_ZONE | G35: 4 | I35: Highest-ranked team from each of the 4 FIE zones among ranks 5–24 | M35: If a zone has no team in ranks 5–24, the place goes to the next highest-ranked team overall, irrespective of zone. | N35: 20 | P35: D.1 | Q35: FROM_IOC_DOC | T35: =IF(AND(COUNTIF(Competitions!A:A,B35)+COUNTIF(Ranking_Systems!A:A,B35)+COUNTIF(Olympic_Events!A:A,B35)+IF(OR(B35="HOST_USA",B35="TRIPARTITE"),1,0)>0,COUNTIF(Competitions!A:A,D35)+COUNTIF(Ranking_Systems!A:A,D35)+COUNTIF(Olympic_Events!A:A,D35)>0),"OK","BROKEN") -> OK
A36: fen-035 | B36: fie-individual-senior-aor | C36: RANKING | D36: la28-fencing-ind-foil-w | E36: OLYMPIC_EVENT | F36: RANKING_CUTOFF | G36: 2 | I36: Top 2 eligible athletes in the Individual Senior AOR | L36: 10 individual places per weapon, but the 24 team-qualified athletes also compete in the individual event without holding one of these 10. The individual field is 34–37 while the individual quota is 10. | M36: Max 1 athlete per NOC per weapon. AOR already excludes NOCs qualified via team. | N36: 30 | P36: D.2 | Q36: FROM_IOC_DOC | T36: =IF(AND(COUNTIF(Competitions!A:A,B36)+COUNTIF(Ranking_Systems!A:A,B36)+COUNTIF(Olympic_Events!A:A,B36)+IF(OR(B36="HOST_USA",B36="TRIPARTITE"),1,0)>0,COUNTIF(Competitions!A:A,D36)+COUNTIF(Ranking_Systems!A:A,D36)+COUNTIF(Olympic_Events!A:A,D36)>0),"OK","BROKEN") -> OK
A37: fen-036 | B37: fie-individual-senior-aor | C37: RANKING | D37: la28-fencing-ind-foil-w | E37: OLYMPIC_EVENT | F37: RANKING_CUTOFF_BY_ZONE | G37: 4 | I37: Highest-ranked eligible athlete from each of the 4 zones in the AOR by zone | K37: Only if your NOC has NOT already qualified in this weapon at an earlier cascade stage. | L37: 10 individual places per weapon, but the 24 team-qualified athletes also compete in the individual event without holding one of these 10. The individual field is 34–37 while the individual quota is 10. | M37: Open ONLY to NOCs with no athlete qualified for this weapon via team qualification or the Individual Senior AOR. Max 1 per NOC per weapon. | N37: 40 | P37: D.2 | Q37: FROM_IOC_DOC | T37: =IF(AND(COUNTIF(Competitions!A:A,B37)+COUNTIF(Ranking_Systems!A:A,B37)+COUNTIF(Olympic_Events!A:A,B37)+IF(OR(B37="HOST_USA",B37="TRIPARTITE"),1,0)>0,COUNTIF(Competitions!A:A,D37)+COUNTIF(Ranking_Systems!A:A,D37)+COUNTIF(Olympic_Events!A:A,D37)>0),"OK","BROKEN") -> OK
A38: fen-037 | B38: fie-zonal-qualifying-europe | C38: COMPETITION | D38: la28-fencing-ind-foil-w | E38: OLYMPIC_EVENT | F38: PLACING_ELIGIBLE | G38: 1 | I38: Winner from the Europe zonal qualifying event | K38: Only if your NOC has NOT already qualified in this weapon at an earlier cascade stage. | M38: Open ONLY to NOCs with no athlete qualified for this weapon via team qualification, the Individual Senior AOR, or the AOR by zone. Max 1 per NOC per weapon. | N38: 50 | P38: D.2 | Q38: FROM_IOC_DOC | T38: =IF(AND(COUNTIF(Competitions!A:A,B38)+COUNTIF(Ranking_Systems!A:A,B38)+COUNTIF(Olympic_Events!A:A,B38)+IF(OR(B38="HOST_USA",B38="TRIPARTITE"),1,0)>0,COUNTIF(Competitions!A:A,D38)+COUNTIF(Ranking_Systems!A:A,D38)+COUNTIF(Olympic_Events!A:A,D38)>0),"OK","BROKEN") -> OK
A39: fen-038 | B39: fie-zonal-qualifying-asia-oceania | C39: COMPETITION | D39: la28-fencing-ind-foil-w | E39: OLYMPIC_EVENT | F39: PLACING_ELIGIBLE | G39: 1 | I39: Winner from the Asia-Oceania zonal qualifying event | K39: Only if your NOC has NOT already qualified in this weapon at an earlier cascade stage. | M39: Open ONLY to NOCs with no athlete qualified for this weapon via team qualification, the Individual Senior AOR, or the AOR by zone. Max 1 per NOC per weapon. | N39: 50 | P39: D.2 | Q39: FROM_IOC_DOC | T39: =IF(AND(COUNTIF(Competitions!A:A,B39)+COUNTIF(Ranking_Systems!A:A,B39)+COUNTIF(Olympic_Events!A:A,B39)+IF(OR(B39="HOST_USA",B39="TRIPARTITE"),1,0)>0,COUNTIF(Competitions!A:A,D39)+COUNTIF(Ranking_Systems!A:A,D39)+COUNTIF(Olympic_Events!A:A,D39)>0),"OK","BROKEN") -> OK
A40: fen-039 | B40: fie-zonal-qualifying-americas | C40: COMPETITION | D40: la28-fencing-ind-foil-w | E40: OLYMPIC_EVENT | F40: PLACING_ELIGIBLE | G40: 1 | I40: Winner from the the Americas zonal qualifying event | K40: Only if your NOC has NOT already qualified in this weapon at an earlier cascade stage. | M40: Open ONLY to NOCs with no athlete qualified for this weapon via team qualification, the Individual Senior AOR, or the AOR by zone. Max 1 per NOC per weapon. | N40: 50 | P40: D.2 | Q40: FROM_IOC_DOC | T40: =IF(AND(COUNTIF(Competitions!A:A,B40)+COUNTIF(Ranking_Systems!A:A,B40)+COUNTIF(Olympic_Events!A:A,B40)+IF(OR(B40="HOST_USA",B40="TRIPARTITE"),1,0)>0,COUNTIF(Competitions!A:A,D40)+COUNTIF(Ranking_Systems!A:A,D40)+COUNTIF(Olympic_Events!A:A,D40)>0),"OK","BROKEN") -> OK
...

Sheet Ranking_Systems
A1: ranking_id | B1: name | C1: governing_body | D1: sport | E1: gender | F1: standings_url | G1: window_start | H1: window_end | I1: cutoff_date | J1: selection_rule_type | K1: selection_n | L1: nation_cap | M1: excludes_already_qualified | N1: feeds_id | O1: points_model_type | P1: points_notes | Q1: min_events | R1: decay_notes | S1: source_ref | T1: confidence
A2: fie-senior-team-ranking | B2: FIE Official Senior Team Ranking List | C2: FIE | D2: Fencing | E2: X | F2: https://fie.org/ | G2: 2027-04-01 | H2: 2028-04-01 | I2: 2028-04-01 | J2: SEE_LINKS | L2: ONE_TEAM_PER_NOC_PER_WEAPON | M2: NO | N2: 6 team events | O2: DOCUMENTED | P2: Points per article o.109 of the FIE Organisation Rules. Ranked separately per weapon. | R2: Only results 1 Apr 2027 – 1 Apr 2028 count. | S2: D.1 | T2: FROM_IOC_DOC
A3: fie-individual-senior-aor | B3: FIE Individual Senior Adjusted Official Ranking (AOR) | C3: FIE | D3: Fencing | E3: X | F3: https://fie.org/ | G3: 2027-04-01 | H3: 2028-04-01 | I3: 2028-04-01 | J3: SEE_LINKS | L3: ONE_ATHLETE_PER_NOC_PER_WEAPON | M3: YES | N3: 6 individual events | O3: DERIVED | P3: Base ranking = points per article o.108. AOR then REMOVES every athlete whose NOC qualified via team qualification, and keeps only the highest-ranked athlete per NOC per zone per weapon. Cannot be read off the published ranking — must be recomputed after team qualification resolves. | R3: Only results 1 Apr 2027 – 1 Apr 2028 count. | S3: D.2 | T3: FROM_IOC_DOC
A4: icc-mens-t20i-team-ranking | B4: ICC Men’s T20I Team Rankings | C4: ICC | D4: Cricket | E4: M | F4: https://www.icc-cricket.com/rankings/about | H4: 2026-12-31 | I4: 2026-12-31 | J4: SEE_LINKS | L4: ONE_TEAM_PER_NOC | M4: YES | N4: la28-cricket-m | O4: DERIVED | P4: ICC rating points are published and computable, BUT the Olympic-eligible order is a filtered view: West Indies holds a ranking position yet cannot take a quota place, and of the British nations only England counts. Asymmetry to watch: WI is skipped for the D.1 continental places but DOES count toward the eight FOGQT slots, and if it lands there a West Indies Nations Regional Tournament is convened. The ICC has since named the four continents used for the direct places: Africa, Asia, Europe and Oceania, each subject to a top-15 proviso. | R4: Window closes 31 Dec 2026. Results after that date cannot affect men’s qualification. | S4: D.1, D.3, H | T4: FROM_IOC_DOC
